{"uuid": "3b6df6a8-51d5-42e8-badb-2feb2725d14c", "children": ["7a44251c-34fb-4a06-af2c-9719b56eb50c", "f6fa8f30-6b0e-4531-9bd3-c6bdaadfa012", "cfb4f0cb-085e-47b2-a310-b294b0837ce0", "7dfcd80e-eb04-4d3d-a46d-a3cfc3ad3d72"], "befores": [{"name": "beforeClass", "status": "broken", "statusDetails": {"message": "selenium.common.exceptions.SeleniumManagerException: Message: Selenium Manager failed for: C:\\Users\\vs34\\AppData\\Local\\Programs\\Python\\Python311\\Lib\\site-packages\\selenium\\webdriver\\common\\windows\\selenium-manager.exe --browser chrome --output json.\nThe chromedriver version cannot be discovered\n\n", "trace": "  File \"C:\\Users\\vs34\\AppData\\Local\\Programs\\Python\\Python311\\Lib\\site-packages\\pluggy\\_callers.py\", line 80, in _multicall\n    res = hook_impl.function(*args)\n          ^^^^^^^^^^^^^^^^^^^^^^^^^\n  File \"C:\\Users\\vs34\\AppData\\Local\\Programs\\Python\\Python311\\Lib\\site-packages\\_pytest\\fixtures.py\", line 1130, in pytest_fixture_setup\n    result = call_fixture_func(fixturefunc, request, kwargs)\n             ^^^^^^^^^^^^^^^^^^^^^^^^^^^^^^^^^^^^^^^^^^^^^^^\n  File \"C:\\Users\\vs34\\AppData\\Local\\Programs\\Python\\Python311\\Lib\\site-packages\\_pytest\\fixtures.py\", line 902, in call_fixture_func\n    fixture_result = next(generator)\n                     ^^^^^^^^^^^^^^^\n  File \"C:\\Users\\vs34\\PycharmProjects\\seleniumproj\\SeleniumFrameWork\\tests\\conftest.py\", line 10, in beforeClass\n    driver = driver1.get_web_driver(\"chrome\")\n             ^^^^^^^^^^^^^^^^^^^^^^^^^^^^^^^^\n  File \"C:\\Users\\vs34\\PycharmProjects\\seleniumproj\\SeleniumFrameWork\\base\\DriverClass.py\", line 8, in get_web_driver\n    driver = webdriver.Chrome()\n             ^^^^^^^^^^^^^^^^^^\n  File \"C:\\Users\\vs34\\AppData\\Local\\Programs\\Python\\Python311\\Lib\\site-packages\\selenium\\webdriver\\chrome\\webdriver.py\", line 82, in __init__\n    service.path = DriverFinder.get_path(service, options)\n                   ^^^^^^^^^^^^^^^^^^^^^^^^^^^^^^^^^^^^^^^\n  File \"C:\\Users\\vs34\\AppData\\Local\\Programs\\Python\\Python311\\Lib\\site-packages\\selenium\\webdriver\\common\\driver_finder.py\", line 43, in get_path\n    raise err\n  File \"C:\\Users\\vs34\\AppData\\Local\\Programs\\Python\\Python311\\Lib\\site-packages\\selenium\\webdriver\\common\\driver_finder.py\", line 40, in get_path\n    path = shutil.which(service.path) or SeleniumManager().driver_location(options)\n                                         ^^^^^^^^^^^^^^^^^^^^^^^^^^^^^^^^^^^^^^^^^^\n  File \"C:\\Users\\vs34\\AppData\\Local\\Programs\\Python\\Python311\\Lib\\site-packages\\selenium\\webdriver\\common\\selenium_manager.py\", line 101, in driver_location\n    result = self.run(args)\n             ^^^^^^^^^^^^^^\n  File \"C:\\Users\\vs34\\AppData\\Local\\Programs\\Python\\Python311\\Lib\\site-packages\\selenium\\webdriver\\common\\selenium_manager.py\", line 122, in run\n    raise SeleniumManagerException(f\"Selenium Manager failed for: {command}.\\n{result}{stderr}\")\n"}, "start": 1708509119384, "stop": 1708509123998}], "start": 1708509119384, "stop": 1708509124456}