{"uuid": "0717df6e-c0c6-4dd3-b264-cba4a8b0f476", "children": ["fae3040e-c61e-4c3a-8aa7-80529e7957be", "f0e2cfb9-7dfd-4972-a335-28a508f6b634", "b6c0339d-2587-4724-9f95-812f4d4f5c37", "66fb13dc-26cd-4ddd-a20f-91b903a1806d", "6940923b-f578-4e41-9b4a-41fb153c652d", "183b5319-7d18-4b1e-b855-44e97a2d0008", "dadc2d5a-8bf2-4fc4-93b3-43fe561694e2"], "befores": [{"name": "beforeClass", "status": "broken", "statusDetails": {"message": "selenium.common.exceptions.SeleniumManagerException: Message: Selenium Manager failed for: C:\\Users\\vs34\\AppData\\Local\\Programs\\Python\\Python311\\Lib\\site-packages\\selenium\\webdriver\\common\\windows\\selenium-manager.exe --browser chrome --output json.\nThe chromedriver version cannot be discovered\n\n", "trace": "  File \"C:\\Users\\vs34\\AppData\\Local\\Programs\\Python\\Python311\\Lib\\site-packages\\pluggy\\_callers.py\", line 80, in _multicall\n    res = hook_impl.function(*args)\n          ^^^^^^^^^^^^^^^^^^^^^^^^^\n  File \"C:\\Users\\vs34\\AppData\\Local\\Programs\\Python\\Python311\\Lib\\site-packages\\_pytest\\fixtures.py\", line 1130, in pytest_fixture_setup\n    result = call_fixture_func(fixturefunc, request, kwargs)\n             ^^^^^^^^^^^^^^^^^^^^^^^^^^^^^^^^^^^^^^^^^^^^^^^\n  File \"C:\\Users\\vs34\\AppData\\Local\\Programs\\Python\\Python311\\Lib\\site-packages\\_pytest\\fixtures.py\", line 902, in call_fixture_func\n    fixture_result = next(generator)\n                     ^^^^^^^^^^^^^^^\n  File \"C:\\Users\\vs34\\PycharmProjects\\seleniumproj\\SeleniumFrameWork\\tests\\conftest.py\", line 10, in beforeClass\n    driver = driver1.get_web_driver(\"chrome\")\n             ^^^^^^^^^^^^^^^^^^^^^^^^^^^^^^^^\n  File \"C:\\Users\\vs34\\PycharmProjects\\seleniumproj\\SeleniumFrameWork\\base\\DriverClass.py\", line 8, in get_web_driver\n    driver = webdriver.Chrome()\n             ^^^^^^^^^^^^^^^^^^\n  File \"C:\\Users\\vs34\\AppData\\Local\\Programs\\Python\\Python311\\Lib\\site-packages\\selenium\\webdriver\\chrome\\webdriver.py\", line 82, in __init__\n    service.path = DriverFinder.get_path(service, options)\n                   ^^^^^^^^^^^^^^^^^^^^^^^^^^^^^^^^^^^^^^^\n  File \"C:\\Users\\vs34\\AppData\\Local\\Programs\\Python\\Python311\\Lib\\site-packages\\selenium\\webdriver\\common\\driver_finder.py\", line 43, in get_path\n    raise err\n  File \"C:\\Users\\vs34\\AppData\\Local\\Programs\\Python\\Python311\\Lib\\site-packages\\selenium\\webdriver\\common\\driver_finder.py\", line 40, in get_path\n    path = shutil.which(service.path) or SeleniumManager().driver_location(options)\n                                         ^^^^^^^^^^^^^^^^^^^^^^^^^^^^^^^^^^^^^^^^^^\n  File \"C:\\Users\\vs34\\AppData\\Local\\Programs\\Python\\Python311\\Lib\\site-packages\\selenium\\webdriver\\common\\selenium_manager.py\", line 101, in driver_location\n    result = self.run(args)\n             ^^^^^^^^^^^^^^\n  File \"C:\\Users\\vs34\\AppData\\Local\\Programs\\Python\\Python311\\Lib\\site-packages\\selenium\\webdriver\\common\\selenium_manager.py\", line 122, in run\n    raise SeleniumManagerException(f\"Selenium Manager failed for: {command}.\\n{result}{stderr}\")\n"}, "start": 1708509113353, "stop": 1708509118517}], "start": 1708509113353, "stop": 1708509119346}