{"uuid": "877695ba-2d24-416b-b55f-5a2fe549442e", "children": ["51924425-b720-4f4b-b1f0-cbbf2848bff4", "de2e5dd0-4aaa-408f-b522-68c52f817e4c", "818ac63b-d592-46c5-86a5-0a7d743d4169", "14233106-3169-4278-87ad-c9ff8506419d", "f2975482-9e3b-48a4-b593-ce18e07ba967"], "befores": [{"name": "beforeClass", "status": "broken", "statusDetails": {"message": "selenium.common.exceptions.SeleniumManagerException: Message: Selenium Manager failed for: C:\\Users\\vs34\\AppData\\Local\\Programs\\Python\\Python311\\Lib\\site-packages\\selenium\\webdriver\\common\\windows\\selenium-manager.exe --browser chrome --output json.\nThe chromedriver version cannot be discovered\n\n", "trace": "  File \"C:\\Users\\vs34\\AppData\\Local\\Programs\\Python\\Python311\\Lib\\site-packages\\pluggy\\_callers.py\", line 80, in _multicall\n    res = hook_impl.function(*args)\n          ^^^^^^^^^^^^^^^^^^^^^^^^^\n  File \"C:\\Users\\vs34\\AppData\\Local\\Programs\\Python\\Python311\\Lib\\site-packages\\_pytest\\fixtures.py\", line 1130, in pytest_fixture_setup\n    result = call_fixture_func(fixturefunc, request, kwargs)\n             ^^^^^^^^^^^^^^^^^^^^^^^^^^^^^^^^^^^^^^^^^^^^^^^\n  File \"C:\\Users\\vs34\\AppData\\Local\\Programs\\Python\\Python311\\Lib\\site-packages\\_pytest\\fixtures.py\", line 902, in call_fixture_func\n    fixture_result = next(generator)\n                     ^^^^^^^^^^^^^^^\n  File \"C:\\Users\\vs34\\PycharmProjects\\seleniumproj\\SeleniumFrameWork\\tests\\conftest.py\", line 10, in beforeClass\n    driver = driver1.get_web_driver(\"chrome\")\n             ^^^^^^^^^^^^^^^^^^^^^^^^^^^^^^^^\n  File \"C:\\Users\\vs34\\PycharmProjects\\seleniumproj\\SeleniumFrameWork\\base\\DriverClass.py\", line 8, in get_web_driver\n    driver = webdriver.Chrome()\n             ^^^^^^^^^^^^^^^^^^\n  File \"C:\\Users\\vs34\\AppData\\Local\\Programs\\Python\\Python311\\Lib\\site-packages\\selenium\\webdriver\\chrome\\webdriver.py\", line 82, in __init__\n    service.path = DriverFinder.get_path(service, options)\n                   ^^^^^^^^^^^^^^^^^^^^^^^^^^^^^^^^^^^^^^^\n  File \"C:\\Users\\vs34\\AppData\\Local\\Programs\\Python\\Python311\\Lib\\site-packages\\selenium\\webdriver\\common\\driver_finder.py\", line 43, in get_path\n    raise err\n  File \"C:\\Users\\vs34\\AppData\\Local\\Programs\\Python\\Python311\\Lib\\site-packages\\selenium\\webdriver\\common\\driver_finder.py\", line 40, in get_path\n    path = shutil.which(service.path) or SeleniumManager().driver_location(options)\n                                         ^^^^^^^^^^^^^^^^^^^^^^^^^^^^^^^^^^^^^^^^^^\n  File \"C:\\Users\\vs34\\AppData\\Local\\Programs\\Python\\Python311\\Lib\\site-packages\\selenium\\webdriver\\common\\selenium_manager.py\", line 101, in driver_location\n    result = self.run(args)\n             ^^^^^^^^^^^^^^\n  File \"C:\\Users\\vs34\\AppData\\Local\\Programs\\Python\\Python311\\Lib\\site-packages\\selenium\\webdriver\\common\\selenium_manager.py\", line 122, in run\n    raise SeleniumManagerException(f\"Selenium Manager failed for: {command}.\\n{result}{stderr}\")\n"}, "start": 1708509146608, "stop": 1708509151624}], "start": 1708509146608, "stop": 1708509152256}