{"uuid": "e757822c-4429-4fc1-8606-2c6137ae746d", "children": ["09777745-d3ec-41f6-a482-37fd741be025", "cbb4b929-da2c-4926-8352-7bdc2182a6d8", "a022b6ee-c05a-411e-9769-bf5799fbc0af", "57da3034-b38e-4683-9d65-06e9fdbba601"], "befores": [{"name": "beforeClass", "status": "broken", "statusDetails": {"message": "selenium.common.exceptions.SeleniumManagerException: Message: Selenium Manager failed for: C:\\Users\\vs34\\AppData\\Local\\Programs\\Python\\Python311\\Lib\\site-packages\\selenium\\webdriver\\common\\windows\\selenium-manager.exe --browser chrome --output json.\nThe chromedriver version cannot be discovered\n\n", "trace": "  File \"C:\\Users\\vs34\\AppData\\Local\\Programs\\Python\\Python311\\Lib\\site-packages\\pluggy\\_callers.py\", line 80, in _multicall\n    res = hook_impl.function(*args)\n          ^^^^^^^^^^^^^^^^^^^^^^^^^\n  File \"C:\\Users\\vs34\\AppData\\Local\\Programs\\Python\\Python311\\Lib\\site-packages\\_pytest\\fixtures.py\", line 1130, in pytest_fixture_setup\n    result = call_fixture_func(fixturefunc, request, kwargs)\n             ^^^^^^^^^^^^^^^^^^^^^^^^^^^^^^^^^^^^^^^^^^^^^^^\n  File \"C:\\Users\\vs34\\AppData\\Local\\Programs\\Python\\Python311\\Lib\\site-packages\\_pytest\\fixtures.py\", line 902, in call_fixture_func\n    fixture_result = next(generator)\n                     ^^^^^^^^^^^^^^^\n  File \"C:\\Users\\vs34\\PycharmProjects\\seleniumproj\\SeleniumFrameWork\\tests\\conftest.py\", line 10, in beforeClass\n    driver = driver1.get_web_driver(\"chrome\")\n             ^^^^^^^^^^^^^^^^^^^^^^^^^^^^^^^^\n  File \"C:\\Users\\vs34\\PycharmProjects\\seleniumproj\\SeleniumFrameWork\\base\\DriverClass.py\", line 8, in get_web_driver\n    driver = webdriver.Chrome()\n             ^^^^^^^^^^^^^^^^^^\n  File \"C:\\Users\\vs34\\AppData\\Local\\Programs\\Python\\Python311\\Lib\\site-packages\\selenium\\webdriver\\chrome\\webdriver.py\", line 82, in __init__\n    service.path = DriverFinder.get_path(service, options)\n                   ^^^^^^^^^^^^^^^^^^^^^^^^^^^^^^^^^^^^^^^\n  File \"C:\\Users\\vs34\\AppData\\Local\\Programs\\Python\\Python311\\Lib\\site-packages\\selenium\\webdriver\\common\\driver_finder.py\", line 43, in get_path\n    raise err\n  File \"C:\\Users\\vs34\\AppData\\Local\\Programs\\Python\\Python311\\Lib\\site-packages\\selenium\\webdriver\\common\\driver_finder.py\", line 40, in get_path\n    path = shutil.which(service.path) or SeleniumManager().driver_location(options)\n                                         ^^^^^^^^^^^^^^^^^^^^^^^^^^^^^^^^^^^^^^^^^^\n  File \"C:\\Users\\vs34\\AppData\\Local\\Programs\\Python\\Python311\\Lib\\site-packages\\selenium\\webdriver\\common\\selenium_manager.py\", line 101, in driver_location\n    result = self.run(args)\n             ^^^^^^^^^^^^^^\n  File \"C:\\Users\\vs34\\AppData\\Local\\Programs\\Python\\Python311\\Lib\\site-packages\\selenium\\webdriver\\common\\selenium_manager.py\", line 122, in run\n    raise SeleniumManagerException(f\"Selenium Manager failed for: {command}.\\n{result}{stderr}\")\n"}, "start": 1708590351880, "stop": 1708590359901}], "start": 1708590351880, "stop": 1708590360315}